<?xml version="1.0"?>

<robot name="duo">
  <!-- Link Definitions -->
  <link name="base_reference">
    <!-- Invisible reference link -->
    <inertial>
      <origin xyz="0 0 0" rpy="0 0 0"/>
      <mass value="0.001"/>
      <inertia ixx="0.001" ixy="0" ixz="0" iyy="0.001" iyz="0" izz="0.001"/>
    </inertial>
  </link>

  <link name="dummy_link">
    <inertial>
      <origin xyz="0 0 0" rpy="0 0 0"/>
      <mass value="0.5"/>
      <inertia ixx="0.02083333333333333" ixy="0" ixz="0" iyy="0.010833333333333334" iyz="0" izz="0.03083333333333333"/>
    </inertial>
  </link>  
  
  <link name="base_link">
    <visual>
      <geometry>
        <box size="0.16 0.14 0.004"/>
      </geometry>
      <material name="green">
        <color rgba="0 1 0 1"/>
      </material>
    </visual>
    <collision>
      <geometry>
        <box size="0.16 0.14 0.004"/>
      </geometry>
    </collision>
  </link>

  <link name="ultrasonic_sensor">
    <inertial>
      <mass value="0.01"/>
      <origin xyz="0 0 0" rpy="0 0 0"/>
      <inertia ixx="0.0001" ixy="0.0" ixz="0.0" iyy="0.0001" iyz="0.0" izz="0.0001"/>
    </inertial>
    <visual>
      <origin xyz="0 0 0" rpy="0 0 0"/>
      <geometry>
        <box size="0.046 0.02 0.021"/>
      </geometry>
      <material name="grey">
        <color rgba="0.5 0.5 0.5 1"/>
      </material>
    </visual>
    <collision>
      <origin xyz="0 0 0" rpy="0 0 0"/>
      <geometry>
        <box size="0.046 0.02 0.021"/>
      </geometry>
    </collision>
  </link>

  <joint name="ultrasonic_joint" type="fixed">
    <parent link="base_link"/>
    <child link="ultrasonic_sensor"/>
    <origin xyz="0 -0.07 0.015" rpy="0 0 0"/>
  </joint>

  <link name="left_wheel">
    <inertial>
      <origin xyz="0 0 0" rpy="0 0 0"/>
      <mass value="0.1"/>
      <inertia ixx="0.0002708333333333334" ixy="0" ixz="0" iyy="0.0002708333333333334" iyz="0" izz="0.0005000000000000001"/>
    </inertial>  
    <visual>
      <geometry>
        <cylinder radius="0.033" length="0.02"/>
      </geometry>
      <material name="black">
        <color rgba="0 0 0 1"/>
      </material>
    </visual>
    <collision>
      <geometry>
        <cylinder radius="0.033" length="0.02"/>
      </geometry>
    </collision>
  </link>

  <transmission name="left_wheel_trans">
  <type>transmission_interface/SimpleTransmission</type>
  <joint name="left_wheel_joint">
    <hardwareInterface>hardware_interface/PositionJointInterface</hardwareInterface>
  </joint>
  <actuator name="left_motor">
    <hardwareInterface>hardware_interface/PositionJointInterface</hardwareInterface>
  </actuator>
</transmission>

  <link name="right_wheel">
    <inertial>
      <origin xyz="0 0 0" rpy="0 0 0"/>
      <mass value="0.1"/>
      <inertia ixx="0.0002708333333333334" ixy="0" ixz="0" iyy="0.0002708333333333334" iyz="0" izz="0.0005000000000000001"/>
    </inertial>  
    <visual>
      <geometry>
        <cylinder radius="0.033" length="0.02"/>
      </geometry>
      <material name="black">
        <color rgba="0 0 0 1"/>
      </material>
    </visual>
    <collision>
      <geometry>
        <cylinder radius="0.033" length="0.02"/>
      </geometry>
    </collision>
  </link>

  <transmission name="right_wheel_trans">
  <type>transmission_interface/SimpleTransmission</type>
  <joint name="right_wheel_joint">
    <hardwareInterface>hardware_interface/PositionJointInterface</hardwareInterface>
  </joint>
  <actuator name="right_motor">
    <hardwareInterface>hardware_interface/PositionJointInterface</hardwareInterface>
  </actuator>
</transmission>

  <link name="caster_wheel">
    <inertial>
      <origin xyz="0 0 0" rpy="0 0 0"/>
      <mass value="0.05"/>
      <inertia ixx="3.291666666666667e-05" ixy="0" ixz="0" iyy="3.291666666666667e-05" iyz="0" izz="6.250000000000001e-05"/>
    </inertial>
    <visual>
      <geometry>
        <cylinder radius="0.015" length="0.025"/>
      </geometry>
      <material name="black">
        <color rgba="0 0 0 1"/>
      </material>
    </visual>
    <collision>
      <geometry>
        <cylinder radius="0.015" length="0.025"/>
      </geometry>
    </collision>
  </link>

  <link name="caster_mount">
    <inertial>
      <origin xyz="0 0 0" rpy="0 0 0"/>
      <mass value="0.1"/>
      <inertia ixx="8.666666666666668e-05" ixy="0" ixz="0" iyy="8.666666666666668e-05" iyz="0" izz="0.00016666666666666672"/>
    </inertial>  
    <visual>
      <geometry>
        <box size="0.02 0.02 0.002"/>
      </geometry>
      <material name="gray">
        <color rgba="0.5 0.5 0.5 1"/>
      </material>
    </visual>
  </link>

  <!-- New link for the rod -->
  <link name="caster_rod">
    <inertial>
      <origin xyz="0 0 0" rpy="0 0 0"/>
      <mass value="0.02"/>
      <inertia ixx="0.00002" ixy="0" ixz="0" iyy="0.00002" iyz="0" izz="0.00004"/>
    </inertial>
    <visual>
      <geometry>
        <cylinder radius="0.005" length="0.025"/>  <!-- Rod length set to 2.5 cm -->
      </geometry>
      <material name="white">
        <color rgba="1 1 1 1"/>
      </material>
    </visual>
    <collision>
      <geometry>
        <cylinder radius="0.005" length="0.025"/>
      </geometry>
    </collision>
  </link>

  <!-- Joint Definitions -->
  <joint name="base_reference_to_base_link" type="fixed">
    <parent link="base_reference" />
    <child link="base_link" />
    <origin xyz="0 0 0.032" rpy="0 0 0" /> <!-- Adjust the height here -->
  </joint>

  <joint name="base_link_to_dummy_link" type="fixed">
    <parent link="base_link" />
    <child link="dummy_link" />
    <origin xyz="0 0 0" rpy="0 0 0" />
  </joint> 

  <joint name="left_wheel_joint" type="continuous">
    <parent link="base_link"/>
    <child link="left_wheel"/>
    <origin xyz="0.093 0.07 -0.02" rpy="0 1.5708 0"/>
    <axis xyz="0 0 1"/>
  </joint>

  <joint name="right_wheel_joint" type="continuous">
    <parent link="base_link"/>
    <child link="right_wheel"/>
    <origin xyz="-0.093 0.07 -0.02" rpy="0 1.5708 0"/>
    <axis xyz="0 0 1"/>
  </joint>

  <joint name="caster_mount_joint" type="fixed">
    <parent link="base_link"/>
    <child link="caster_mount"/>
    <origin xyz="0 -0.07 -0.002" rpy="0 0 0"/>
  </joint>

  <!-- Joint to connect the caster_mount to the caster_rod -->
  <joint name="caster_mount_to_rod_joint" type="continuous">
    <parent link="caster_mount"/>
    <child link="caster_rod"/>
    <origin xyz="0 0 -0.0125" rpy="0 0 1.5708"/>  <!-- Rod positioned under the mount -->
    <axis xyz="0 0 1"/>
  </joint>

  <!-- Joint to connect the caster_rod to the caster_wheel -->
  <joint name="caster_rod_to_wheel_joint" type="fixed">
    <parent link="caster_rod"/>
    <child link="caster_wheel"/>
    <origin xyz="0 0 -0.0125" rpy="0 0 0"/>  <!-- Positioning the wheel at the end of the rod -->
  </joint>

  <joint name="caster_wheel_joint" type="continuous">
    <parent link="caster_mount"/>
    <child link="caster_wheel"/>
    <origin xyz="0 0 -0.03" rpy="0 1.570 0"/>
    <axis xyz="0 0 1"/>
  </joint>
</robot>


  <!-- Diff Drive Plugin -->
  <gazebo>
  <plugin name="ignition::gazebo::systems::DiffDrive" filename="libignition-gazebo-diff-drive-system.so">
    <left_joint>left_wheel_joint</left_joint>
    <right_joint>right_wheel_joint</right_joint>
    <wheel_separation>0.14</wheel_separation>
    <wheel_radius>0.033</wheel_radius>
    <topic>/cmd_vel</topic>
    <odom_topic>/odom</odom_topic>
    <odometry_frame>odom</odometry_frame>
    <robot_base_frame>base_footprint</robot_base_frame>
    <update_rate>100</update_rate>
  </plugin>

  <!-- Ultrasonic Sensor Plugin -->
  
  <plugin name="ultrasonic_sensor_plugin" filename="libgazebo_ros_range.so">
      <ros>
        <namespace>/</namespace>
        <argument>sensor</argument>
        <remapping>sensor_topic:=ultrasonic</remapping>
      </ros>
      <update_rate>10.0</update_rate>
      <frameName>ultrasonic_sensor</frameName>
      <rangeMin>0.02</rangeMin>
      <rangeMax>4.0</rangeMax>
      <radius>0.01</radius>
      <alwaysOn>true</alwaysOn>
      <visualize>true</visualize>
  </plugin>  

</gazebo>

</robot>
